<robot name="box2D">
    
  <link name="baselink">
    <inertial>
      <origin rpy="0 0 0" xyz="0 0 0"/>
       <mass value="0"/>
       <inertia ixx="0" ixy="0" ixz="0" iyy="0" iyz="0" izz="0"/>
    </inertial>
  </link>

  <link name="link1">
    <inertial>
      <origin rpy="0 0 0" xyz="1.0 0 0"/>
       <mass value="0.5"/>
       <inertia ixx="0.0001" ixy="0" ixz="0" iyy="0.0001" iyz="0" izz="0.0001"/>
    </inertial>

    <visual>
      <origin rpy="0 0 0" xyz="1.0 0 0"/>
      <geometry>
        <box size="2 0.1 0.1" />      
      </geometry>     
      <material name="green">
        <color rgba="0 1 0 1"/>
      </material>
    </visual>
    
    <collision>
      <origin rpy="0 0 0" xyz="1.0 0 0"/>
      <geometry>
        <box size="2 0.1 0.1" />      
      </geometry>
    </collision>
  </link>


  <link name="link2">
    <inertial>
      <origin rpy="0 0 0" xyz="1.0 0 0"/>
       <mass value="0.5"/>
       <inertia ixx="0.0001" ixy="0" ixz="0" iyy="0.0001" iyz="0" izz="0.0001"/>
    </inertial>

    <visual>
      <origin rpy="0 0 0" xyz="1.0 0 0"/>
      <geometry>
        <box size="2 0.1 0.1" />      
      </geometry>
      <material name="red">
        <color rgba="1 0 0 1"/>
      </material>
    </visual>
    
    <collision>
      <origin rpy="0 0 0" xyz="1.0 0 0"/>
      <geometry>
        <box size="2 0.1 0.1" />      
      </geometry>
    </collision>
  </link>


  <link name="link3">
    <inertial>
      <origin rpy="0 0 0" xyz="1.0 0 0"/>
       <mass value="0.5"/>
       <inertia ixx="0.0001" ixy="0" ixz="0" iyy="0.0001" iyz="0" izz="0.0001"/>
    </inertial>

    <visual>
      <origin rpy="0 0 0" xyz="1.0 0 0"/>
      <geometry>
        <box size="2 0.1 0.1" />      
      </geometry>
      <material name="blue">
        <color rgba="0 0 1 1"/>
      </material>
    </visual>
    
    <collision>
      <origin rpy="0 0 0" xyz="1.0 0 0"/>
      <geometry>
        <box size="2 0.1 0.1" />      
      </geometry>
    </collision>
  </link>


  <link name="link4">
    <inertial>
      <origin rpy="0 0 0" xyz="1.0 0 0"/>
       <mass value="0.5"/>
       <inertia ixx="0.0001" ixy="0" ixz="0" iyy="0.0001" iyz="0" izz="0.0001"/>
    </inertial>

    <visual>
      <origin rpy="0 0 0" xyz="1.0 0 0"/>
      <geometry>
        <box size="2 0.1 0.1" />      
      </geometry>
      <material name="purple">
        <color rgba="1 0 1 1"/>
      </material>
    </visual>
    
    <collision>
      <origin rpy="0 0 0" xyz="1.0 0 0"/>
      <geometry>
        <box size="2 0.1 0.1" />      
      </geometry>
    </collision>
  </link>


  <link name="link5">
    <inertial>
      <origin rpy="0 0 0" xyz="0 0 0"/>
       <mass value="0.5"/>
       <inertia ixx="0.0001" ixy="0" ixz="0" iyy="0.0001" iyz="0" izz="0.0001"/>
    </inertial>

    <visual>
      <origin rpy="0 0 0" xyz="0 0 0"/>
      <geometry>
        <cylinder radius="0.2" length="0.1"/>
      </geometry>
      <material name="black">
        <color rgba="0 0 0 1"/>
      </material>
    </visual>
    
    <collision>
      <origin rpy="0 0 0" xyz="0 0 0"/>
      <geometry>
        <cylinder radius="0.2" length="0.1"/>
      </geometry>
    </collision>
  </link>



  <joint name = "joint1" type = "revolute">
    <origin xyz = "0.0 0.0 0.0" rpy = "0 0 0"/> 
    <parent link = "baselink" />
    <child link= "link1"/>
    <axis xyz = "0 0 1" />
    <limit effort="1.0" lower="-10000" upper="10000" velocity="10000" />
    <dynamics damping = "0.0" friction="0.0" />
  </joint>

  <joint name = "joint2" type = "revolute">
    <origin xyz = "2.0 0.0 0.0" rpy = "0 0 0"/> 
    <parent link = "link1" />
    <child link= "link2"/>
    <axis xyz = "0 0 1" />
    <limit effort="1.0" lower="-10000" upper="10000" velocity="10000" />
    <dynamics damping = "0.0" friction="0.0" />
  </joint> 

  <joint name = "joint3" type = "revolute">
    <origin xyz = "2.0 0.0 0.0" rpy = "0 0 0"/> 
    <parent link = "link2" />
    <child link= "link3"/>
    <axis xyz = "0 0 1" />
    <limit effort="1.0" lower="-10000" upper="10000" velocity="10000" />
    <dynamics damping = "0.0" friction="0.0" />
  </joint> 

  <joint name = "joint4" type = "revolute">
    <origin xyz = "2.0 0.0 0.0" rpy = "0 0 0"/> 
    <parent link = "link3" />
    <child link= "link4"/>
    <axis xyz = "0 0 1" />
    <limit effort="1.0" lower="-10000" upper="10000" velocity="10000" />
    <dynamics damping = "0.0" friction="0.0" />
  </joint> 

  <joint name = "joint5" type = "fixed">
    <origin xyz = "2.0 0.0 0.0" rpy = "0 0 0"/> 
    <parent link = "link4" />
    <child link= "link5"/>
    <axis xyz = "0 0 1" />
    <limit effort="1.0" lower="-10000" upper="10000" velocity="10000" />
    <dynamics damping = "0.0" friction="0.0" />
  </joint> 

    
</robot>
