<robot name="ypaddle2D">
    
  <link name="base_link">
    <inertial>
      <origin rpy="0 0 0" xyz="0 0 0"/>
       <mass value="0"/>
       <inertia ixx="0" ixy="0" ixz="0" iyy="0" iyz="0" izz="0"/>
    </inertial>
  </link>

  <link name="x_link">
    <inertial>
      <origin rpy="0 0 0" xyz="0 0 0"/>
       <mass value="0.0001"/>
       <inertia ixx="0.0001" ixy="0" ixz="0" iyy="0.0001" iyz="0" izz="0.0001"/>
    </inertial>
  </link>


  <link name="y_link">
    <inertial>
      <origin rpy="0 0 0" xyz="0 0 0"/>
       <mass value="0.0001"/>
       <inertia ixx="0.0001" ixy="0" ixz="0" iyy="0.0001" iyz="0" izz="0.0001"/>
    </inertial>
  </link>


  <link name="theta_link">
    <inertial>
      <origin rpy="0 0 0" xyz="0 0 0"/>
       <mass value="1.0"/>
       <inertia ixx="0.0001" ixy="0" ixz="0" iyy="0.0001" iyz="0" izz="0.0001"/>
    </inertial>

    <visual>
      <origin rpy="0 0 0" xyz="0 0 0"/>
      <geometry>
        <box size="3.75 50 0.2" />      
      </geometry>
      <material name="white">
        <color rgba="1 0.5 0 1"/>
      </material>
    </visual>
    
    <collision>
      <origin rpy="0 0 0" xyz="0 0 0"/>
      <geometry>
        <box size="3.75 50 0.2" />
      </geometry>
    </collision>
  </link>

  <joint name = "x_prismatic" type = "prismatic">
    <origin xyz = "0.0 0.0 0.0" rpy = "0 0 0"/> 
    <parent link = "base_link"/>
    <child link= "x_link"/>
    <axis xyz = "1 0 0"/>
    <limit effort="1.0" lower="-10000" upper="10000" velocity="10000" />
    <dynamics damping = "0.0" friction="0.0" />
  </joint>

  <joint name = "y_prismatic" type = "prismatic">
    <origin xyz = "0.0 0.0 0.0" rpy = "0 0 0"/> 
    <parent link = "x_link" />
    <child link= "y_link"/>
    <axis xyz = "0 1 0" />
    <limit effort="1.0" lower="-10000" upper="10000" velocity="10000" />
    <dynamics damping = "0.0" friction="0.0" />
  </joint>

   <joint name = "theta_revolute" type = "revolute">
    <origin xyz = "0.0 0.0 0.0" rpy = "0 0 0"/> 
    <parent link = "y_link" />
    <child link= "theta_link"/>
    <axis xyz = "0 0 1" />
    <limit effort="1.0" lower="-10000" upper="10000" velocity="10000" />
    <dynamics damping = "0.0" friction="0.0" />
  </joint>

    
</robot>